ERROR:    | 2023-03-03 12:51:37 | (sqlite3.IntegrityError) UNIQUE constraint failed: admin_route_response.route_path
[SQL: UPDATE admin_route_response SET name=?, route_path=?, description=? WHERE admin_route_response.id = ?]
[parameters: ('adding address changed', 'address_delete_changed', 'employee address posting changed', 2)]
(Background on this error at: https://sqlalche.me/e/14/gkpj)
Traceback (most recent call last):
  File "/home/bushu/.local/share/virtualenvs/openerp-vNWIj9jV/lib/python3.11/site-packages/sqlalchemy/engine/base.py", line 1900, in _execute_context
    self.dialect.do_execute(
  File "/home/bushu/.local/share/virtualenvs/openerp-vNWIj9jV/lib/python3.11/site-packages/sqlalchemy/engine/default.py", line 736, in do_execute
    cursor.execute(statement, parameters)
  File "/home/bushu/.local/share/virtualenvs/openerp-vNWIj9jV/lib/python3.11/site-packages/sqlalchemy/dialects/sqlite/aiosqlite.py", line 108, in execute
    self._adapt_connection._handle_exception(error)
  File "/home/bushu/.local/share/virtualenvs/openerp-vNWIj9jV/lib/python3.11/site-packages/sqlalchemy/dialects/sqlite/aiosqlite.py", line 236, in _handle_exception
    raise error
  File "/home/bushu/.local/share/virtualenvs/openerp-vNWIj9jV/lib/python3.11/site-packages/sqlalchemy/dialects/sqlite/aiosqlite.py", line 90, in execute
    self.await_(_cursor.execute(operation, parameters))
  File "/home/bushu/.local/share/virtualenvs/openerp-vNWIj9jV/lib/python3.11/site-packages/sqlalchemy/util/_concurrency_py3k.py", line 68, in await_only
    return current.driver.switch(awaitable)
           ^^^^^^^^^^^^^^^^^^^^^^^^^^^^^^^^
  File "/home/bushu/.local/share/virtualenvs/openerp-vNWIj9jV/lib/python3.11/site-packages/sqlalchemy/util/_concurrency_py3k.py", line 121, in greenlet_spawn
    value = await result
            ^^^^^^^^^^^^
  File "/home/bushu/.local/share/virtualenvs/openerp-vNWIj9jV/lib/python3.11/site-packages/aiosqlite/cursor.py", line 37, in execute
    await self._execute(self._cursor.execute, sql, parameters)
  File "/home/bushu/.local/share/virtualenvs/openerp-vNWIj9jV/lib/python3.11/site-packages/aiosqlite/cursor.py", line 31, in _execute
    return await self._conn._execute(fn, *args, **kwargs)
           ^^^^^^^^^^^^^^^^^^^^^^^^^^^^^^^^^^^^^^^^^^^^^^
  File "/home/bushu/.local/share/virtualenvs/openerp-vNWIj9jV/lib/python3.11/site-packages/aiosqlite/core.py", line 137, in _execute
    return await future
           ^^^^^^^^^^^^
  File "/home/bushu/.local/share/virtualenvs/openerp-vNWIj9jV/lib/python3.11/site-packages/aiosqlite/core.py", line 110, in run
    result = function()
             ^^^^^^^^^^
sqlite3.IntegrityError: UNIQUE constraint failed: admin_route_response.route_path

The above exception was the direct cause of the following exception:

Traceback (most recent call last):
  File "/home/bushu/Documents/Charms/openerp/users/responses/routepath.py", line 44, in response_path_patch
    await session.execute(update(RouteResponse).where(RouteResponse.id == route_id).values(**my_route.dict()))
  File "/home/bushu/.local/share/virtualenvs/openerp-vNWIj9jV/lib/python3.11/site-packages/sqlalchemy/ext/asyncio/session.py", line 214, in execute
    result = await greenlet_spawn(
             ^^^^^^^^^^^^^^^^^^^^^
  File "/home/bushu/.local/share/virtualenvs/openerp-vNWIj9jV/lib/python3.11/site-packages/sqlalchemy/util/_concurrency_py3k.py", line 126, in greenlet_spawn
    result = context.throw(*sys.exc_info())
             ^^^^^^^^^^^^^^^^^^^^^^^^^^^^^^
  File "/home/bushu/.local/share/virtualenvs/openerp-vNWIj9jV/lib/python3.11/site-packages/sqlalchemy/orm/session.py", line 1714, in execute
    result = conn._execute_20(statement, params or {}, execution_options)
             ^^^^^^^^^^^^^^^^^^^^^^^^^^^^^^^^^^^^^^^^^^^^^^^^^^^^^^^^^^^^
  File "/home/bushu/.local/share/virtualenvs/openerp-vNWIj9jV/lib/python3.11/site-packages/sqlalchemy/engine/base.py", line 1705, in _execute_20
    return meth(self, args_10style, kwargs_10style, execution_options)
           ^^^^^^^^^^^^^^^^^^^^^^^^^^^^^^^^^^^^^^^^^^^^^^^^^^^^^^^^^^^
  File "/home/bushu/.local/share/virtualenvs/openerp-vNWIj9jV/lib/python3.11/site-packages/sqlalchemy/sql/elements.py", line 334, in _execute_on_connection
    return connection._execute_clauseelement(
           ^^^^^^^^^^^^^^^^^^^^^^^^^^^^^^^^^^
  File "/home/bushu/.local/share/virtualenvs/openerp-vNWIj9jV/lib/python3.11/site-packages/sqlalchemy/engine/base.py", line 1572, in _execute_clauseelement
    ret = self._execute_context(
          ^^^^^^^^^^^^^^^^^^^^^^
  File "/home/bushu/.local/share/virtualenvs/openerp-vNWIj9jV/lib/python3.11/site-packages/sqlalchemy/engine/base.py", line 1943, in _execute_context
    self._handle_dbapi_exception(
  File "/home/bushu/.local/share/virtualenvs/openerp-vNWIj9jV/lib/python3.11/site-packages/sqlalchemy/engine/base.py", line 2124, in _handle_dbapi_exception
    util.raise_(
  File "/home/bushu/.local/share/virtualenvs/openerp-vNWIj9jV/lib/python3.11/site-packages/sqlalchemy/util/compat.py", line 211, in raise_
    raise exception
  File "/home/bushu/.local/share/virtualenvs/openerp-vNWIj9jV/lib/python3.11/site-packages/sqlalchemy/engine/base.py", line 1900, in _execute_context
    self.dialect.do_execute(
  File "/home/bushu/.local/share/virtualenvs/openerp-vNWIj9jV/lib/python3.11/site-packages/sqlalchemy/engine/default.py", line 736, in do_execute
    cursor.execute(statement, parameters)
  File "/home/bushu/.local/share/virtualenvs/openerp-vNWIj9jV/lib/python3.11/site-packages/sqlalchemy/dialects/sqlite/aiosqlite.py", line 108, in execute
    self._adapt_connection._handle_exception(error)
  File "/home/bushu/.local/share/virtualenvs/openerp-vNWIj9jV/lib/python3.11/site-packages/sqlalchemy/dialects/sqlite/aiosqlite.py", line 236, in _handle_exception
    raise error
  File "/home/bushu/.local/share/virtualenvs/openerp-vNWIj9jV/lib/python3.11/site-packages/sqlalchemy/dialects/sqlite/aiosqlite.py", line 90, in execute
    self.await_(_cursor.execute(operation, parameters))
  File "/home/bushu/.local/share/virtualenvs/openerp-vNWIj9jV/lib/python3.11/site-packages/sqlalchemy/util/_concurrency_py3k.py", line 68, in await_only
    return current.driver.switch(awaitable)
           ^^^^^^^^^^^^^^^^^^^^^^^^^^^^^^^^
  File "/home/bushu/.local/share/virtualenvs/openerp-vNWIj9jV/lib/python3.11/site-packages/sqlalchemy/util/_concurrency_py3k.py", line 121, in greenlet_spawn
    value = await result
            ^^^^^^^^^^^^
  File "/home/bushu/.local/share/virtualenvs/openerp-vNWIj9jV/lib/python3.11/site-packages/aiosqlite/cursor.py", line 37, in execute
    await self._execute(self._cursor.execute, sql, parameters)
  File "/home/bushu/.local/share/virtualenvs/openerp-vNWIj9jV/lib/python3.11/site-packages/aiosqlite/cursor.py", line 31, in _execute
    return await self._conn._execute(fn, *args, **kwargs)
           ^^^^^^^^^^^^^^^^^^^^^^^^^^^^^^^^^^^^^^^^^^^^^^
  File "/home/bushu/.local/share/virtualenvs/openerp-vNWIj9jV/lib/python3.11/site-packages/aiosqlite/core.py", line 137, in _execute
    return await future
           ^^^^^^^^^^^^
  File "/home/bushu/.local/share/virtualenvs/openerp-vNWIj9jV/lib/python3.11/site-packages/aiosqlite/core.py", line 110, in run
    result = function()
             ^^^^^^^^^^
sqlalchemy.exc.IntegrityError: (sqlite3.IntegrityError) UNIQUE constraint failed: admin_route_response.route_path
[SQL: UPDATE admin_route_response SET name=?, route_path=?, description=? WHERE admin_route_response.id = ?]
[parameters: ('adding address changed', 'address_delete_changed', 'employee address posting changed', 2)]
(Background on this error at: https://sqlalche.me/e/14/gkpj)
