[32mINFO    [0m sqlalchemy.engine.Engine:base.py:2614 BEGIN (implicit)
[32mINFO    [0m sqlalchemy.engine.Engine:base.py:1572 INSERT INTO admin_user (uid, email, password, date_registered, disabled) VALUES (?, ?, ?, CURRENT_TIMESTAMP, ?)
[32mINFO    [0m sqlalchemy.engine.Engine:base.py:1572 [cached since 0.5281s ago] ('5b210465-696e-4e04-b834-202c2423ea47', 'beimdegefu@gmail.com', '$pbkdf2-sha512$25000$LEXIOQeAUArBWMv5v9faG.Pcm9N6L4XQ2jvn3Jtzzvnfe885Z6y1dq51bs25Nwbg/F9rDcE4JyQkpJTyvjfGuDdmLCWkdO6d896bE.L8f28$7eneEY8cAOr.1NhZQF7Kxu4vlDnarcpPwGlx6Iv4uZN049GBQqQMSsHg.5sN0VDqkPfTbTb2xke2cvyvYMAi4g', 0)
[32mINFO    [0m sqlalchemy.engine.Engine:base.py:2617 ROLLBACK
[1m[31mERROR   [0m erp_logger:register.py:15 (sqlite3.IntegrityError) UNIQUE constraint failed: admin_user.email
[SQL: INSERT INTO admin_user (uid, email, password, date_registered, disabled) VALUES (?, ?, ?, CURRENT_TIMESTAMP, ?)]
[parameters: ('5b210465-696e-4e04-b834-202c2423ea47', 'beimdegefu@gmail.com', '$pbkdf2-sha512$25000$LEXIOQeAUArBWMv5v9faG.Pcm9N6L4XQ2jvn3Jtzzvnfe885Z6y1dq51bs25Nwbg/F9rDcE4JyQkpJTyvjfGuDdmLCWkdO6d896bE.L8f28$7eneEY8cAOr.1NhZQF7Kxu4vlDnarcpPwGlx6Iv4uZN049GBQqQMSsHg.5sN0VDqkPfTbTb2xke2cvyvYMAi4g', 0)]
(Background on this error at: https://sqlalche.me/e/14/gkpj)
Traceback (most recent call last):
  File "/home/bushu/.local/share/virtualenvs/openerp-vNWIj9jV/lib/python3.11/site-packages/sqlalchemy/engine/base.py", line 1900, in _execute_context
    self.dialect.do_execute(
  File "/home/bushu/.local/share/virtualenvs/openerp-vNWIj9jV/lib/python3.11/site-packages/sqlalchemy/engine/default.py", line 736, in do_execute
    cursor.execute(statement, parameters)
  File "/home/bushu/.local/share/virtualenvs/openerp-vNWIj9jV/lib/python3.11/site-packages/sqlalchemy/dialects/sqlite/aiosqlite.py", line 108, in execute
    self._adapt_connection._handle_exception(error)
  File "/home/bushu/.local/share/virtualenvs/openerp-vNWIj9jV/lib/python3.11/site-packages/sqlalchemy/dialects/sqlite/aiosqlite.py", line 236, in _handle_exception
    raise error
  File "/home/bushu/.local/share/virtualenvs/openerp-vNWIj9jV/lib/python3.11/site-packages/sqlalchemy/dialects/sqlite/aiosqlite.py", line 90, in execute
    self.await_(_cursor.execute(operation, parameters))
  File "/home/bushu/.local/share/virtualenvs/openerp-vNWIj9jV/lib/python3.11/site-packages/sqlalchemy/util/_concurrency_py3k.py", line 68, in await_only
    return current.driver.switch(awaitable)
           ^^^^^^^^^^^^^^^^^^^^^^^^^^^^^^^^
  File "/home/bushu/.local/share/virtualenvs/openerp-vNWIj9jV/lib/python3.11/site-packages/sqlalchemy/util/_concurrency_py3k.py", line 121, in greenlet_spawn
    value = await result
            ^^^^^^^^^^^^
  File "/home/bushu/.local/share/virtualenvs/openerp-vNWIj9jV/lib/python3.11/site-packages/aiosqlite/cursor.py", line 37, in execute
    await self._execute(self._cursor.execute, sql, parameters)
  File "/home/bushu/.local/share/virtualenvs/openerp-vNWIj9jV/lib/python3.11/site-packages/aiosqlite/cursor.py", line 31, in _execute
    return await self._conn._execute(fn, *args, **kwargs)
           ^^^^^^^^^^^^^^^^^^^^^^^^^^^^^^^^^^^^^^^^^^^^^^
  File "/home/bushu/.local/share/virtualenvs/openerp-vNWIj9jV/lib/python3.11/site-packages/aiosqlite/core.py", line 137, in _execute
    return await future
           ^^^^^^^^^^^^
  File "/home/bushu/.local/share/virtualenvs/openerp-vNWIj9jV/lib/python3.11/site-packages/aiosqlite/core.py", line 110, in run
    result = function()
             ^^^^^^^^^^
sqlite3.IntegrityError: UNIQUE constraint failed: admin_user.email

The above exception was the direct cause of the following exception:

Traceback (most recent call last):
  File "/home/bushu/Documents/Charms/openerp/users/responses/register.py", line 11, in register
    await session.commit()
  File "/home/bushu/.local/share/virtualenvs/openerp-vNWIj9jV/lib/python3.11/site-packages/sqlalchemy/ext/asyncio/session.py", line 582, in commit
    return await greenlet_spawn(self.sync_session.commit)
           ^^^^^^^^^^^^^^^^^^^^^^^^^^^^^^^^^^^^^^^^^^^^^^
  File "/home/bushu/.local/share/virtualenvs/openerp-vNWIj9jV/lib/python3.11/site-packages/sqlalchemy/util/_concurrency_py3k.py", line 128, in greenlet_spawn
    result = context.switch(value)
             ^^^^^^^^^^^^^^^^^^^^^
  File "/home/bushu/.local/share/virtualenvs/openerp-vNWIj9jV/lib/python3.11/site-packages/sqlalchemy/orm/session.py", line 1451, in commit
    self._transaction.commit(_to_root=self.future)
  File "/home/bushu/.local/share/virtualenvs/openerp-vNWIj9jV/lib/python3.11/site-packages/sqlalchemy/orm/session.py", line 829, in commit
    self._prepare_impl()
  File "/home/bushu/.local/share/virtualenvs/openerp-vNWIj9jV/lib/python3.11/site-packages/sqlalchemy/orm/session.py", line 808, in _prepare_impl
    self.session.flush()
  File "/home/bushu/.local/share/virtualenvs/openerp-vNWIj9jV/lib/python3.11/site-packages/sqlalchemy/orm/session.py", line 3444, in flush
    self._flush(objects)
  File "/home/bushu/.local/share/virtualenvs/openerp-vNWIj9jV/lib/python3.11/site-packages/sqlalchemy/orm/session.py", line 3583, in _flush
    with util.safe_reraise():
  File "/home/bushu/.local/share/virtualenvs/openerp-vNWIj9jV/lib/python3.11/site-packages/sqlalchemy/util/langhelpers.py", line 70, in __exit__
    compat.raise_(
  File "/home/bushu/.local/share/virtualenvs/openerp-vNWIj9jV/lib/python3.11/site-packages/sqlalchemy/util/compat.py", line 211, in raise_
    raise exception
  File "/home/bushu/.local/share/virtualenvs/openerp-vNWIj9jV/lib/python3.11/site-packages/sqlalchemy/orm/session.py", line 3544, in _flush
    flush_context.execute()
  File "/home/bushu/.local/share/virtualenvs/openerp-vNWIj9jV/lib/python3.11/site-packages/sqlalchemy/orm/unitofwork.py", line 456, in execute
    rec.execute(self)
  File "/home/bushu/.local/share/virtualenvs/openerp-vNWIj9jV/lib/python3.11/site-packages/sqlalchemy/orm/unitofwork.py", line 630, in execute
    util.preloaded.orm_persistence.save_obj(
  File "/home/bushu/.local/share/virtualenvs/openerp-vNWIj9jV/lib/python3.11/site-packages/sqlalchemy/orm/persistence.py", line 245, in save_obj
    _emit_insert_statements(
  File "/home/bushu/.local/share/virtualenvs/openerp-vNWIj9jV/lib/python3.11/site-packages/sqlalchemy/orm/persistence.py", line 1238, in _emit_insert_statements
    result = connection._execute_20(
             ^^^^^^^^^^^^^^^^^^^^^^^
  File "/home/bushu/.local/share/virtualenvs/openerp-vNWIj9jV/lib/python3.11/site-packages/sqlalchemy/engine/base.py", line 1705, in _execute_20
    return meth(self, args_10style, kwargs_10style, execution_options)
           ^^^^^^^^^^^^^^^^^^^^^^^^^^^^^^^^^^^^^^^^^^^^^^^^^^^^^^^^^^^
  File "/home/bushu/.local/share/virtualenvs/openerp-vNWIj9jV/lib/python3.11/site-packages/sqlalchemy/sql/elements.py", line 334, in _execute_on_connection
    return connection._execute_clauseelement(
           ^^^^^^^^^^^^^^^^^^^^^^^^^^^^^^^^^^
  File "/home/bushu/.local/share/virtualenvs/openerp-vNWIj9jV/lib/python3.11/site-packages/sqlalchemy/engine/base.py", line 1572, in _execute_clauseelement
    ret = self._execute_context(
          ^^^^^^^^^^^^^^^^^^^^^^
  File "/home/bushu/.local/share/virtualenvs/openerp-vNWIj9jV/lib/python3.11/site-packages/sqlalchemy/engine/base.py", line 1943, in _execute_context
    self._handle_dbapi_exception(
  File "/home/bushu/.local/share/virtualenvs/openerp-vNWIj9jV/lib/python3.11/site-packages/sqlalchemy/engine/base.py", line 2124, in _handle_dbapi_exception
    util.raise_(
  File "/home/bushu/.local/share/virtualenvs/openerp-vNWIj9jV/lib/python3.11/site-packages/sqlalchemy/util/compat.py", line 211, in raise_
    raise exception
  File "/home/bushu/.local/share/virtualenvs/openerp-vNWIj9jV/lib/python3.11/site-packages/sqlalchemy/engine/base.py", line 1900, in _execute_context
    self.dialect.do_execute(
  File "/home/bushu/.local/share/virtualenvs/openerp-vNWIj9jV/lib/python3.11/site-packages/sqlalchemy/engine/default.py", line 736, in do_execute
    cursor.execute(statement, parameters)
  File "/home/bushu/.local/share/virtualenvs/openerp-vNWIj9jV/lib/python3.11/site-packages/sqlalchemy/dialects/sqlite/aiosqlite.py", line 108, in execute
    self._adapt_connection._handle_exception(error)
  File "/home/bushu/.local/share/virtualenvs/openerp-vNWIj9jV/lib/python3.11/site-packages/sqlalchemy/dialects/sqlite/aiosqlite.py", line 236, in _handle_exception
    raise error
  File "/home/bushu/.local/share/virtualenvs/openerp-vNWIj9jV/lib/python3.11/site-packages/sqlalchemy/dialects/sqlite/aiosqlite.py", line 90, in execute
    self.await_(_cursor.execute(operation, parameters))
  File "/home/bushu/.local/share/virtualenvs/openerp-vNWIj9jV/lib/python3.11/site-packages/sqlalchemy/util/_concurrency_py3k.py", line 68, in await_only
    return current.driver.switch(awaitable)
           ^^^^^^^^^^^^^^^^^^^^^^^^^^^^^^^^
  File "/home/bushu/.local/share/virtualenvs/openerp-vNWIj9jV/lib/python3.11/site-packages/sqlalchemy/util/_concurrency_py3k.py", line 121, in greenlet_spawn
    value = await result
            ^^^^^^^^^^^^
  File "/home/bushu/.local/share/virtualenvs/openerp-vNWIj9jV/lib/python3.11/site-packages/aiosqlite/cursor.py", line 37, in execute
    await self._execute(self._cursor.execute, sql, parameters)
  File "/home/bushu/.local/share/virtualenvs/openerp-vNWIj9jV/lib/python3.11/site-packages/aiosqlite/cursor.py", line 31, in _execute
    return await self._conn._execute(fn, *args, **kwargs)
           ^^^^^^^^^^^^^^^^^^^^^^^^^^^^^^^^^^^^^^^^^^^^^^
  File "/home/bushu/.local/share/virtualenvs/openerp-vNWIj9jV/lib/python3.11/site-packages/aiosqlite/core.py", line 137, in _execute
    return await future
           ^^^^^^^^^^^^
  File "/home/bushu/.local/share/virtualenvs/openerp-vNWIj9jV/lib/python3.11/site-packages/aiosqlite/core.py", line 110, in run
    result = function()
             ^^^^^^^^^^
sqlalchemy.exc.IntegrityError: (sqlite3.IntegrityError) UNIQUE constraint failed: admin_user.email
[SQL: INSERT INTO admin_user (uid, email, password, date_registered, disabled) VALUES (?, ?, ?, CURRENT_TIMESTAMP, ?)]
[parameters: ('5b210465-696e-4e04-b834-202c2423ea47', 'beimdegefu@gmail.com', '$pbkdf2-sha512$25000$LEXIOQeAUArBWMv5v9faG.Pcm9N6L4XQ2jvn3Jtzzvnfe885Z6y1dq51bs25Nwbg/F9rDcE4JyQkpJTyvjfGuDdmLCWkdO6d896bE.L8f28$7eneEY8cAOr.1NhZQF7Kxu4vlDnarcpPwGlx6Iv4uZN049GBQqQMSsHg.5sN0VDqkPfTbTb2xke2cvyvYMAi4g', 0)]
(Background on this error at: https://sqlalche.me/e/14/gkpj)